<?xml version="1.0" ?>
<!--Following tutorial: https://gazebosim.org/docs/harmonic/building_robot/-->>

<sdf version="1.10">
    <world name="car_world">
        <physics name="1ms" type="ignored">
            <max_step_size>0.001</max_step_size>
            <real_time_factor>1.0</real_time_factor>
        </physics>

        <plugin
            filename="gz-sim-physics-system"
            name="gz::sim::systems::Physics">
        </plugin>

        <plugin
            filename="gz-sim-user-commands-system"
            name="gz::sim::systems::UserCommands">
        </plugin>

        <plugin
            filename="gz-sim-scene-broadcaster-system"
            name="gz::sim::systems::SceneBroadcaster">
        </plugin>

        <plugin 
            filename="gz-sim-imu-system"
            name="gz::sim::systems::Imu">
        </plugin>

        <plugin 
            filename="gz-sim-contact-system"
            name="gz::sim::systems::Contact">
        </plugin>

        <plugin
            filename="gz-sim-sensors-system"
            name="gz::sim::systems::Sensors">
            <render_engine>ogre2</render_engine>
        </plugin>

        <light type="directional" name="sun">
            <cast_shadows>true</cast_shadows>
            <pose>0 0 10 0 0 0</pose>
            <diffuse>0.8 0.8 0.8 1</diffuse>
            <specular>0.2 0.2 0.2 1</specular>
            
            <attenuation>
                <range>1000</range>
                <constant>0.9</constant>
                <linear>0.01</linear>
                <quadratic>0.001</quadratic>
            </attenuation>

            <direction>-0.5 0.1 -0.9</direction>
        </light>

        <model name="ground_plane">
            <static>true</static>
            <link name="link">
                <collision name="collision">
                    <geometry>
                        <plane>
                        <normal>0 0 1</normal>
                        </plane>
                    </geometry>
                </collision>

                <visual name="visual">
                    <geometry>
                        <plane>
                        <normal>0 0 1</normal>
                        <size>100 100</size>
                        </plane>
                    </geometry>

                    <material>
                        <ambient>0.8 0.8 0.8 1</ambient>
                        <diffuse>0.8 0.8 0.8 1</diffuse>
                        <specular>0.8 0.8 0.8 1</specular>
                    </material>
                </visual>
            </link>
        </model>

        <!--Define the vehicle-->
        <model name='vehicle_blue' canonical_link='chassis'>
            <pose relative_to='world'>
                5 8 0 0 0 -1.5708
            </pose>
            
            <link name='chassis'>
                <pose relative_to='__model__'>
                    0.5 0 0.4 0 0 0
                </pose>

                <inertial> 
                    <mass>1.14395</mass>
                    <inertia>
                        <ixx>0.095329</ixx>
                        <ixy>0</ixy>
                        <ixz>0</ixz>
                        <iyy>0.381317</iyy>
                        <iyz>0</iyz>
                        <izz>0.476646</izz>
                    </inertia>
                </inertial>

                <visual name='visual'>
                    <geometry>
                        <box>
                            <size>2.0 1.0 0.5</size>
                        </box>
                    </geometry>
                    <!--let's add color to our link-->
                    <material>
                        <ambient>0.0 0.0 1.0 1</ambient>
                        <diffuse>0.0 0.0 1.0 1</diffuse>
                        <specular>0.0 0.0 1.0 1</specular>
                    </material>
                </visual>

                <collision name='collision'>
                    <geometry>
                        <box>
                            <size>2.0 1.0 0.5</size>
                        </box>
                    </geometry>
                </collision>

                <sensor name="imu_sensor" type="imu">
                    <always_on>1</always_on>
                    <update_rate>1</update_rate>
                    <visualize>true</visualize>
                    <topic>imu</topic>
                </sensor>

                <sensor name='gpu_lidar' type='gpu_lidar'>"
                    <pose relative_to='lidar_frame'>0 0 0 0 0 0</pose>
                    <topic>lidar</topic>
                    <update_rate>10</update_rate>
                    <visualize>true</visualize>
                    <always_on>1</always_on>
                    <ray>
                        <scan>
                            <horizontal>
                                <samples>320</samples>
                                <resolution>1</resolution>
                                <min_angle>-3.14159</min_angle>
                                <max_angle>3.14159</max_angle>
                            </horizontal>
                            <vertical>
                                <samples>1</samples>
                                <resolution>0.01</resolution>
                                <min_angle>0</min_angle>
                                <max_angle>0</max_angle>
                            </vertical>
                        </scan>
                        <range>
                            <min>0.08</min>
                            <max>10.0</max>
                            <resolution>0.01</resolution>
                        </range>
                        <noise>
                            <type>gaussian</type>
                            <mean>0.0</mean>
                            <stddev>0.05</stddev>
                        </noise>
                    </ray>
                </sensor>
            </link>

            <link name='left_wheel'>
                <pose relative_to="chassis">
                    -0.5 0.6 0 -1.5707 0 0
                </pose>

                <inertial>
                    <mass>1</mass>
                    <inertia>
                        <ixx>0.043333</ixx>
                        <ixy>0</ixy>
                        <ixz>0</ixz>
                        <iyy>0.043333</iyy>
                        <iyz>0</iyz>
                        <izz>0.08</izz>
                    </inertia>
                </inertial>

                <visual name='visual'>
                    <geometry>
                        <cylinder>
                            <radius>0.4</radius>
                            <length>0.2</length>
                        </cylinder>
                    </geometry>

                    <material>
                        <ambient>1.0 0.0 0.0 1</ambient>
                        <diffuse>1.0 0.0 0.0 1</diffuse>
                        <specular>1.0 0.0 0.0 1</specular>
                    </material>
                </visual>

                <collision name='collision'>
                    <geometry>
                        <cylinder>
                            <radius>0.4</radius>
                            <length>0.2</length>
                        </cylinder>
                    </geometry>
                </collision>
            </link>

            <!--The same as left wheel but with different position-->
            <link name='right_wheel'>
                <pose relative_to="chassis">-0.5 -0.6 0 -1.5707 0 0</pose> <!--angles are in radian-->
                <inertial>
                    <mass>1</mass>
                    <inertia>
                        <ixx>0.043333</ixx>
                        <ixy>0</ixy>
                        <ixz>0</ixz>
                        <iyy>0.043333</iyy>
                        <iyz>0</iyz>
                        <izz>0.08</izz>
                    </inertia>
                </inertial>
                <visual name='visual'>
                    <geometry>
                        <cylinder>
                            <radius>0.4</radius>
                            <length>0.2</length>
                        </cylinder>
                    </geometry>
                    <material>
                        <ambient>1.0 0.0 0.0 1</ambient>
                        <diffuse>1.0 0.0 0.0 1</diffuse>
                        <specular>1.0 0.0 0.0 1</specular>
                    </material>
                </visual>
                <collision name='collision'>
                    <geometry>
                        <cylinder>
                            <radius>0.4</radius>
                            <length>0.2</length>
                        </cylinder>
                    </geometry>
                </collision>
            </link>

            <frame name="caster_frame" attached_to='chassis'>
                <pose>
                    0.8 0 -0.2 0 0 0
                </pose>
            </frame>

            <!--caster wheel-->
            <link name='caster'>
                <pose relative_to='caster_frame'/>
                <inertial>
                    <mass>1</mass>
                    <inertia>
                        <ixx>0.016</ixx>
                        <ixy>0</ixy>
                        <ixz>0</ixz>
                        <iyy>0.016</iyy>
                        <iyz>0</iyz>
                        <izz>0.016</izz>
                    </inertia>
                </inertial>

                <visual name='visual'>
                    <geometry>
                        <sphere>
                            <radius>0.2</radius>
                        </sphere>
                    </geometry>

                    <material>
                        <ambient>0.0 1 0.0 1</ambient>
                        <diffuse>0.0 1 0.0 1</diffuse>
                        <specular>0.0 1 0.0 1</specular>
                    </material>
                </visual>

                <collision name='collision'>
                    <geometry>
                        <sphere>
                            <radius>0.2</radius>
                        </sphere>
                    </geometry>
                </collision>
            </link>

            <joint name='left_wheel_joint' type='revolute'>
                <pose relative_to='left_wheel'/>

                <parent>chassis</parent>
                <child>left_wheel</child>

                <axis>
                    <xyz expressed_in='__model__'>0 1 0</xyz> <!--can be defined as any frame or even arbitrary frames-->
                    <limit>
                        <lower>-1.79769e+308</lower>    <!--negative infinity-->
                        <upper>1.79769e+308</upper>     <!--positive infinity-->
                    </limit>
                </axis>
            </joint>

            <joint name='right_wheel_joint' type='revolute'>
                <pose relative_to='right_wheel'/>

                <parent>chassis</parent>
                <child>right_wheel</child>

                <axis>
                    <xyz expressed_in='__model__'>0 1 0</xyz>
                    <limit>
                        <lower>-1.79769e+308</lower>    <!--negative infinity-->
                        <upper>1.79769e+308</upper>     <!--positive infinity-->
                    </limit>
                </axis>
            </joint>

            <joint name='caster_wheel' type='ball'>
                <parent>chassis</parent>
                <child>caster</child>
            </joint>

            <plugin filename="gz-sim-diff-drive-system" name="gz::sim::systems::DiffDrive">
                <left_joint>left_wheel_joint</left_joint>
                <right_joint>right_wheel_joint</right_joint>
                <wheel_separation>1.2</wheel_separation>
                <wheel_radius>0.4</wheel_radius>
                <odom_publish_frequency>1</odom_publish_frequency>
                <topic>cmd_vel</topic>
            </plugin>

            <frame name="lidar_frame" attached_to='chassis'>
                <pose>
                    0.8 0 0.5 0 0 0
                </pose>
            </frame>


        
        </model> <!--END VEHICLE CHASSIS MODEL-->

        
            <!-- ———————————————————————————————— -->
        <!-- Additional walls for drawing a block “I” -->
        <!-- ———————————————————————————————— -->

        <!-- ───── Top serif (horizontal) ───── -->
  <model name="wall_top" >
    <static>true</static>
    <!-- centered above corridor at y=7 -->
    <pose>5 9 1.0 0 0 0</pose>
    <link name="box">
      <visual name="visual">
        <geometry><box><size>10.0 0.5 2.0</size></box></geometry>
        <material>
          <ambient>0 0 1 1</ambient><diffuse>0 0 1 1</diffuse><specular>0 0 1 1</specular>
        </material>
      </visual>
      <collision name="collision">
        <geometry><box><size>10.0 0.5 2.0</size></box></geometry>
      </collision>
    </link>
  </model>

  <!-- ───── Bottom serif (horizontal) ───── -->
  <model name="wall_bottom">
    <static>true</static>
    <!-- centered below corridor at y=−5 -->
    <pose>5 -7 1.0 0 0 0</pose>
    <link name="box">
      <visual name="visual">
        <geometry><box><size>10.0 0.5 2.0</size></box></geometry>
        <material>
          <ambient>0 0 1 1</ambient><diffuse>0 0 1 1</diffuse><specular>0 0 1 1</specular>
        </material>
      </visual>
      <collision name="collision">
        <geometry><box><size>10.0 0.5 2.0</size></box></geometry>
      </collision>
    </link>
  </model>

  <!-- ───── Left inner bar (vertical) ───── -->
  <model name="wall_inner_left">
    <static>true</static>
    <!-- narrow bar at x=4.7, spanning the full y-length -->
    <pose>3.65 1 1.0 0 0 0</pose>
    <link name="box">
      <visual name="visual">
        <geometry><box><size>0.2 12.0 2.0</size></box></geometry>
        <material>
          <ambient>0 0 1 1</ambient><diffuse>0 0 1 1</diffuse><specular>0 0 1 1</specular>
        </material>
      </visual>
      <collision name="collision">
        <geometry><box><size>0.2 12.0 2.0</size></box></geometry>
      </collision>
    </link>
  </model>

  <!-- ───── Right inner bar (vertical) ───── -->
  <model name="wall_inner_right">
    <static>true</static>
    <pose>6.35 1 1.0 0 0 0</pose>
    <link name="box">
      <visual name="visual">
        <geometry><box><size>0.2 12.0 2.0</size></box></geometry>
        <material>
          <ambient>0 0 1 1</ambient><diffuse>0 0 1 1</diffuse><specular>0 0 1 1</specular>
        </material>
      </visual>
      <collision name="collision">
        <geometry><box><size>0.2 12.0 2.0</size></box></geometry>
      </collision>
    </link>
  </model>


    </world>

</sdf>